Workbook

Sheet Settings
A1: Counterpart MVP — Plan Settings (Revised)
A3: Edit values in column B. The plan is now scoped around memory + summary + logging, not the full classifier. Dates compute from start date.
A5: Setting | B5: Value | C5: Notes
A6: Plan start date | B6: 2026-05-11 | C6: First working day.
A7: Working days per week | B7: 5 | C7: 5 = mon-fri, 6 = include sat, 7 = include sun.
A8: Hours per working day | B8: 8 | C8: Realistic hours of focused work per day.
A9: Skip weekends | B9: =TRUE() -> TRUE | C9: TRUE = saturdays and sundays non-working.
A10: Founder solo | B10: =TRUE() -> TRUE | C10: TRUE = solo. FALSE = adjust task estimates.
A11: Apply to YC | B11: =TRUE() -> TRUE | C11: TRUE = include YC application milestones.
A12: Target launch day | B12: 30 | C12: Working day number of public launch.
A13: Buffer days at end | B13: 5 | C13: Slippage absorption between core build done and launch.
A16: Workstream legend
A17: Build | B17: Engineering — product, logging, summarization
A18: Marketing | B18: Content, social, audience, founder voice
A19: Research | B19: User interviews, evals, prompt iteration
A20: Ops | B20: Setup, accounts, legal, admin, money
A23: What changed from previous version
A24: 1. Personalization is now memory + summary, not full classifier. Saves ~10 days.
A25: 2. Behavioral logging is now richer — Tier 1 of data collection doc fully implemented at MVP.
A26: 3. Onboarding is more thorough — five forced-choice questions + free text + initial summary generation.
A27: 4. Profile transparency UI is now first-class, not a final-week add-on.
A28: 5. Phase 2 components (full classifier, Bayesian filter, etc.) are deferred until data shows they're needed.
A29: 6. The full classifier plan and prompts document are still valid as Phase 2 reference material.

Sheet Day Plan
A1: Counterpart MVP — Day-by-Day Plan (Revised)
A3: Total tasks | B3: =COUNTA(E7:E500)-1 -> 95 | C3: Tasks done | D3: =COUNTIF(L7:L500,TRUE()) -> 0 | E3: Progress | F3: =IF(B3=0,0,D3/B3) -> 0 | G3: Total hours | H3: =SUM(H7:H500) -> 281 | I3: Hours done | J3: =SUMIF(L7:L500,TRUE(),H7:H500) -> 0 | K3: Target launch | L3: =IF(Settings!$B$9=TRUE(),WORKDAY(Settings!$B$6-1,Settings!$B$12),Settings!$B$6+Settings!$B$12-1) -> 46192
A6: Day | B6: Date | C6: Phase | D6: Workstream | E6: Task | F6: Why this matters | G6: Depends on | H6: Hours | I6: Working | J6: Notes | K6: Blocks | L6: Done
A7: 1 | B7: =IF(Settings!$B$9=TRUE(),WORKDAY(Settings!$B$6-1,A7),Settings!$B$6+A7-1) -> 46153 | C7: 1 — Foundations | D7: Ops | E7: Generate 30-50 candidate product names. Run trademark + domain checks on top 10 | F7: Counterpart name has trademark conflict; rename before any public launch | H7: 4 | I7: =TRUE() -> TRUE | L7: =FALSE() -> FALSE
A8: 1 | B8: =IF(Settings!$B$9=TRUE(),WORKDAY(Settings!$B$6-1,A8),Settings!$B$6+A8-1) -> 46153 | C8: 1 — Foundations | D8: Ops | E8: Create accounts: GitHub, Vercel, Supabase, Anthropic API, Voyage AI | F8: Foundation infrastructure | H8: 2 | I8: =TRUE() -> TRUE | L8: =FALSE() -> FALSE
A9: 1 | B9: =IF(Settings!$B$9=TRUE(),WORKDAY(Settings!$B$6-1,A9),Settings!$B$6+A9-1) -> 46153 | C9: 1 — Foundations | D9: Marketing | E9: Read principles + branding + data collection docs. Draft positioning | F9: Lead with personalization, not anti-sycophancy | H9: 2 | I9: =TRUE() -> TRUE | L9: =FALSE() -> FALSE
A10: 2 | B10: =IF(Settings!$B$9=TRUE(),WORKDAY(Settings!$B$6-1,A10),Settings!$B$6+A10-1) -> 46154 | C10: 1 — Foundations | D10: Ops | E10: Email UK trademark attorney for clearance opinion on top 3 names (£300-700) | F10: Cheaper than later rebrand | G10: 1 | H10: 1 | I10: =TRUE() -> TRUE | L10: =FALSE() -> FALSE
A11: 2 | B11: =IF(Settings!$B$9=TRUE(),WORKDAY(Settings!$B$6-1,A11),Settings!$B$6+A11-1) -> 46154 | C11: 1 — Foundations | D11: Build | E11: Initialize Next.js 14 + TypeScript + Tailwind + shadcn/ui app. Push to GitHub | F11: Frontend scaffold | G11: 1 | H11: 3 | I11: =TRUE() -> TRUE | L11: =FALSE() -> FALSE
A12: 2 | B12: =IF(Settings!$B$9=TRUE(),WORKDAY(Settings!$B$6-1,A12),Settings!$B$6+A12-1) -> 46154 | C12: 1 — Foundations | D12: Build | E12: Set up Codespaces config (.devcontainer) with Claude Code installed | F12: Cross-device dev | G12: 1 | H12: 1 | I12: =TRUE() -> TRUE | L12: =FALSE() -> FALSE
A13: 2 | B13: =IF(Settings!$B$9=TRUE(),WORKDAY(Settings!$B$6-1,A13),Settings!$B$6+A13-1) -> 46154 | C13: 1 — Foundations | D13: Marketing | E13: Set up X account, write profile bio, post intro thread | F13: Audience-building takes 3-6 months. Start now | H13: 1 | I13: =TRUE() -> TRUE | L13: =FALSE() -> FALSE
A14: 2 | B14: =IF(Settings!$B$9=TRUE(),WORKDAY(Settings!$B$6-1,A14),Settings!$B$6+A14-1) -> 46154 | C14: 1 — Foundations | D14: Marketing | E14: Buy domain + reserve handles for top 3 candidate names | F14: Lock identity before final decision | G14: 2 | H14: 1 | I14: =TRUE() -> TRUE | L14: =FALSE() -> FALSE
A15: 3 | B15: =IF(Settings!$B$9=TRUE(),WORKDAY(Settings!$B$6-1,A15),Settings!$B$6+A15-1) -> 46155 | C15: 1 — Foundations | D15: Build | E15: Build schema: users, sessions, messages, response_pairs, onboarding_responses, user_profiles, events tables | F15: Schema from data collection doc § 2. Comprehensive from day 1 | G15: 2 | H15: 5 | I15: =TRUE() -> TRUE | L15: =FALSE() -> FALSE
A16: 3 | B16: =IF(Settings!$B$9=TRUE(),WORKDAY(Settings!$B$6-1,A16),Settings!$B$6+A16-1) -> 46155 | C16: 1 — Foundations | D16: Build | E16: Wire up Supabase Auth (email magic link or Google SSO) | F16: Need user identity for any personalization | G16: 3 | H16: 2 | I16: =TRUE() -> TRUE | L16: =FALSE() -> FALSE
A17: 3 | B17: =IF(Settings!$B$9=TRUE(),WORKDAY(Settings!$B$6-1,A17),Settings!$B$6+A17-1) -> 46155 | C17: 1 — Foundations | D17: Marketing | E17: Build landing page v1: hero + 3 proof points + email capture | F17: Start collecting emails immediately | H17: 1 | I17: =TRUE() -> TRUE | L17: =FALSE() -> FALSE
A18: 4 | B18: =IF(Settings!$B$9=TRUE(),WORKDAY(Settings!$B$6-1,A18),Settings!$B$6+A18-1) -> 46156 | C18: 1 — Foundations | D18: Build | E18: Build minimal chat loop: input → API → Claude Sonnet → display. Working end-to-end | F18: Working product. Foundation for everything | G18: 3 | H18: 4 | I18: =TRUE() -> TRUE | L18: =FALSE() -> FALSE
A19: 4 | B19: =IF(Settings!$B$9=TRUE(),WORKDAY(Settings!$B$6-1,A19),Settings!$B$6+A19-1) -> 46156 | C19: 1 — Foundations | D19: Build | E19: Implement comprehensive message logging: every user + assistant message with all linguistic features | F19: Tier 1 logging from data collection doc. Non-negotiable from day 1 | G19: 4 | H19: 3 | I19: =TRUE() -> TRUE | L19: =FALSE() -> FALSE
A20: 4 | B20: =IF(Settings!$B$9=TRUE(),WORKDAY(Settings!$B$6-1,A20),Settings!$B$6+A20-1) -> 46156 | C20: 1 — Foundations | D20: Marketing | E20: Submit landing page to Indie Hackers; share on personal X | F20: Tiny early audience signal | G20: 3 | H20: 1 | I20: =TRUE() -> TRUE | L20: =FALSE() -> FALSE
A21: 5 | B21: =IF(Settings!$B$9=TRUE(),WORKDAY(Settings!$B$6-1,A21),Settings!$B$6+A21-1) -> 46157 | C21: 1 — Foundations | D21: Build | E21: Implement response_pairs table population: regenerate, time-to-followup, copy detection | F21: The relationship layer. Most analytical questions answered from this table later | G21: 4 | H21: 5 | I21: =TRUE() -> TRUE | L21: =FALSE() -> FALSE
A22: 5 | B22: =IF(Settings!$B$9=TRUE(),WORKDAY(Settings!$B$6-1,A22),Settings!$B$6+A22-1) -> 46157 | C22: 1 — Foundations | D22: Build | E22: Implement session creation, close detection, basic session metrics | F22: Sessions are the unit of analysis for retention | G22: 4 | H22: 2 | I22: =TRUE() -> TRUE | L22: =FALSE() -> FALSE
A23: 5 | B23: =IF(Settings!$B$9=TRUE(),WORKDAY(Settings!$B$6-1,A23),Settings!$B$6+A23-1) -> 46157 | C23: 1 — Foundations | D23: Marketing | E23: Write manifesto essay v1: 'The personal AI thesis' | F23: Long-form artifact for newsletters, HN, YC. Cross-post X+LinkedIn | H23: 1 | I23: =TRUE() -> TRUE | L23: =FALSE() -> FALSE
A24: 6 | B24: =IF(Settings!$B$9=TRUE(),WORKDAY(Settings!$B$6-1,A24),Settings!$B$6+A24-1) -> 46160 | C24: 1 — Foundations | D24: Ops | E24: Write privacy policy + terms of service (Termly or fiverr lawyer) | F24: Privacy posture is a brand feature | H24: 2 | I24: =TRUE() -> TRUE | L24: =FALSE() -> FALSE
A25: 6 | B25: =IF(Settings!$B$9=TRUE(),WORKDAY(Settings!$B$6-1,A25),Settings!$B$6+A25-1) -> 46160 | C25: 1 — Foundations | D25: Build | E25: Set up PostHog analytics, instrument basic frontend events | F25: Behavioral signals + product analytics are different. Need both | G25: 5 | H25: 2 | I25: =TRUE() -> TRUE | L25: =FALSE() -> FALSE
A26: 6 | B26: =IF(Settings!$B$9=TRUE(),WORKDAY(Settings!$B$6-1,A26),Settings!$B$6+A26-1) -> 46160 | C26: 1 — Foundations | D26: Build | E26: Deploy to Vercel; verify chat loop and logging work in production | F26: Local-only doesn't count | G26: 5 | H26: 1 | I26: =TRUE() -> TRUE | L26: =FALSE() -> FALSE
A27: 6 | B27: =IF(Settings!$B$9=TRUE(),WORKDAY(Settings!$B$6-1,A27),Settings!$B$6+A27-1) -> 46160 | C27: 1 — Foundations | D27: Marketing | E27: Publish manifesto essay. Cross-post X thread + LinkedIn | F27: First major content artifact | G27: 5 | H27: 2 | I27: =TRUE() -> TRUE | L27: =FALSE() -> FALSE
A28: 6 | B28: =IF(Settings!$B$9=TRUE(),WORKDAY(Settings!$B$6-1,A28),Settings!$B$6+A28-1) -> 46160 | C28: 1 — Foundations | D28: Marketing | E28: First X build-in-public post with screenshot | F28: Establish cadence | G28: 6 | H28: 1 | I28: =TRUE() -> TRUE | L28: =FALSE() -> FALSE
A29: 7 | B29: =IF(Settings!$B$9=TRUE(),WORKDAY(Settings!$B$6-1,A29),Settings!$B$6+A29-1) -> 46161 | C29: 1 — Foundations | D29: Build | E29: Buffer day: catch up on Phase 1 slippage, refactor, fix bugs | F29: Always slippage. Better to absorb than push forward | H29: 6 | I29: =TRUE() -> TRUE | L29: =FALSE() -> FALSE
A30: 7 | B30: =IF(Settings!$B$9=TRUE(),WORKDAY(Settings!$B$6-1,A30),Settings!$B$6+A30-1) -> 46161 | C30: 1 — Foundations | D30: Marketing | E30: Reply to manifesto comments + X thread engagement | F30: 48h engagement window is critical | G30: 6 | H30: 2 | I30: =TRUE() -> TRUE | L30: =FALSE() -> FALSE
A31: 8 | B31: =IF(Settings!$B$9=TRUE(),WORKDAY(Settings!$B$6-1,A31),Settings!$B$6+A31-1) -> 46162 | C31: 2 — Personalization layer | D31: Build | E31: Build onboarding UI: 5 forced-choice questions + 3 free-text fields with timing capture | F31: Onboarding is the moment users feel personalization first. Critical UX | G31: 7 | H31: 6 | I31: =TRUE() -> TRUE | L31: =FALSE() -> FALSE
A32: 8 | B32: =IF(Settings!$B$9=TRUE(),WORKDAY(Settings!$B$6-1,A32),Settings!$B$6+A32-1) -> 46162 | C32: 2 — Personalization layer | D32: Build | E32: Capture choice durations on frontend (decision speed signal) | F32: Fast choice = confident, slow = deliberation | G32: 8 | H32: 2 | I32: =TRUE() -> TRUE | L32: =FALSE() -> FALSE
A33: 9 | B33: =IF(Settings!$B$9=TRUE(),WORKDAY(Settings!$B$6-1,A33),Settings!$B$6+A33-1) -> 46163 | C33: 2 — Personalization layer | D33: Build | E33: Implement initial profile summary generation: Haiku call from onboarding inputs | F33: First profile = first impression. Has to be good | G33: 8 | H33: 3 | I33: =TRUE() -> TRUE | L33: =FALSE() -> FALSE
A34: 9 | B34: =IF(Settings!$B$9=TRUE(),WORKDAY(Settings!$B$6-1,A34),Settings!$B$6+A34-1) -> 46163 | C34: 2 — Personalization layer | D34: Build | E34: Build user_profiles table with versioning (is_current, version columns) | F34: Old summaries kept for analysis; never overwrite | G34: 9 | H34: 2 | I34: =TRUE() -> TRUE | L34: =FALSE() -> FALSE
A35: 9 | B35: =IF(Settings!$B$9=TRUE(),WORKDAY(Settings!$B$6-1,A35),Settings!$B$6+A35-1) -> 46163 | C35: 2 — Personalization layer | D35: Build | E35: Wire system prompt composer: base + user_summary + session_context | F35: Where personalization actually shows up in responses | G35: 10 | H35: 3 | I35: =TRUE() -> TRUE | L35: =FALSE() -> FALSE
A36: 10 | B36: =IF(Settings!$B$9=TRUE(),WORKDAY(Settings!$B$6-1,A36),Settings!$B$6+A36-1) -> 46164 | C36: 2 — Personalization layer | D36: Build | E36: Implement A/B cohort assignment at signup (with-personalization vs without) | F36: Without this, can't validate that personalization works. CRITICAL non-negotiable | G36: 11 | H36: 3 | I36: =TRUE() -> TRUE | L36: =FALSE() -> FALSE
A37: 10 | B37: =IF(Settings!$B$9=TRUE(),WORKDAY(Settings!$B$6-1,A37),Settings!$B$6+A37-1) -> 46164 | C37: 2 — Personalization layer | D37: Build | E37: Wire cohort into system prompt composer (without-cohort gets base instruction only) | F37: Control group sees generic AI. The comparison is the validation | G37: 12 | H37: 2 | I37: =TRUE() -> TRUE | L37: =FALSE() -> FALSE
A38: 10 | B38: =IF(Settings!$B$9=TRUE(),WORKDAY(Settings!$B$6-1,A38),Settings!$B$6+A38-1) -> 46164 | C38: 2 — Personalization layer | D38: Build | E38: Log cohort_at_generation on every response_pair | F38: Snapshots for future analysis. Must be in row at write time | G38: 12 | H38: 1 | I38: =TRUE() -> TRUE | L38: =FALSE() -> FALSE
A39: 10 | B39: =IF(Settings!$B$9=TRUE(),WORKDAY(Settings!$B$6-1,A39),Settings!$B$6+A39-1) -> 46164 | C39: 2 — Personalization layer | D39: Marketing | E39: Daily X post: build-in-public update on architecture | F39: Cadence | H39: 1 | I39: =TRUE() -> TRUE | L39: =FALSE() -> FALSE
A40: 11 | B40: =IF(Settings!$B$9=TRUE(),WORKDAY(Settings!$B$6-1,A40),Settings!$B$6+A40-1) -> 46167 | C40: 2 — Personalization layer | D40: Build | E40: Build session_close detection background job (5min cadence, 30min idle threshold) | F40: Sessions close themselves; don't depend on user explicit action | G40: 10 | H40: 3 | I40: =TRUE() -> TRUE | L40: =FALSE() -> FALSE
A41: 11 | B41: =IF(Settings!$B$9=TRUE(),WORKDAY(Settings!$B$6-1,A41),Settings!$B$6+A41-1) -> 46167 | C41: 2 — Personalization layer | D41: Build | E41: Implement summarization job: load profile + session, call Haiku, write new version | F41: The compounding personalization mechanism. Heart of the MVP | G41: 13 | H41: 4 | I41: =TRUE() -> TRUE | L41: =FALSE() -> FALSE
A42: 12 | B42: =IF(Settings!$B$9=TRUE(),WORKDAY(Settings!$B$6-1,A42),Settings!$B$6+A42-1) -> 46168 | C42: 2 — Personalization layer | D42: Build | E42: Frontend typing instrumentation: typing_started_at, typing_duration, edit_count, paste_event_count | F42: Tier 2 logging. Reveals cognitive load patterns | G42: 11 | H42: 4 | I42: =TRUE() -> TRUE | L42: =FALSE() -> FALSE
A43: 12 | B43: =IF(Settings!$B$9=TRUE(),WORKDAY(Settings!$B$6-1,A43),Settings!$B$6+A43-1) -> 46168 | C43: 2 — Personalization layer | D43: Build | E43: Frontend scroll/read instrumentation on responses | F43: Reading depth is high-signal for response quality | G43: 15 | H43: 3 | I43: =TRUE() -> TRUE | L43: =FALSE() -> FALSE
...

Sheet Workstreams
A1: Workstreams Summary
A3: Counts auto-update from Day Plan.
A5: Workstream | B5: Tasks | C5: Done | D5: Hours total | E5: % Complete
A6: Build | B6: =COUNTIF('Day Plan'!$D$7:$D$102,A6) -> 49 | C6: =COUNTIFS('Day Plan'!$D$7:$D$102,A6,'Day Plan'!$L$7:$L$102,TRUE()) -> 0 | D6: =SUMIF('Day Plan'!$D$7:$D$102,A6,'Day Plan'!$H$7:$H$102) -> 166 | E6: =IF(B6=0,0,C6/B6) -> 0
A7: Marketing | B7: =COUNTIF('Day Plan'!$D$7:$D$102,A7) -> 30 | C7: =COUNTIFS('Day Plan'!$D$7:$D$102,A7,'Day Plan'!$L$7:$L$102,TRUE()) -> 0 | D7: =SUMIF('Day Plan'!$D$7:$D$102,A7,'Day Plan'!$H$7:$H$102) -> 69 | E7: =IF(B7=0,0,C7/B7) -> 0
A8: Research | B8: =COUNTIF('Day Plan'!$D$7:$D$102,A8) -> 9 | C8: =COUNTIFS('Day Plan'!$D$7:$D$102,A8,'Day Plan'!$L$7:$L$102,TRUE()) -> 0 | D8: =SUMIF('Day Plan'!$D$7:$D$102,A8,'Day Plan'!$H$7:$H$102) -> 27 | E8: =IF(B8=0,0,C8/B8) -> 0
A9: Ops | B9: =COUNTIF('Day Plan'!$D$7:$D$102,A9) -> 8 | C9: =COUNTIFS('Day Plan'!$D$7:$D$102,A9,'Day Plan'!$L$7:$L$102,TRUE()) -> 0 | D9: =SUMIF('Day Plan'!$D$7:$D$102,A9,'Day Plan'!$H$7:$H$102) -> 19 | E9: =IF(B9=0,0,C9/B9) -> 0
A10: Total | B10: =SUM(B6:B9) -> 96 | C10: =SUM(C6:C9) -> 0 | D10: =SUM(D6:D9) -> 281 | E10: =IF(B10=0,0,C10/B10) -> 0
A13: By phase
A14: Phase | B14: Tasks | C14: Done | D14: Hours | E14: % Complete
A15: 1 — Foundations | B15: =COUNTIF('Day Plan'!$C$7:$C$102,A15) -> 24 | C15: =COUNTIFS('Day Plan'!$C$7:$C$102,A15,'Day Plan'!$L$7:$L$102,TRUE()) -> 0 | D15: =SUMIF('Day Plan'!$C$7:$C$102,A15,'Day Plan'!$H$7:$H$102) -> 55 | E15: =IF(B15=0,0,C15/B15) -> 0
A16: 2 — Personalization layer | B16: =COUNTIF('Day Plan'!$C$7:$C$102,A16) -> 22 | C16: =COUNTIFS('Day Plan'!$C$7:$C$102,A16,'Day Plan'!$L$7:$L$102,TRUE()) -> 0 | D16: =SUMIF('Day Plan'!$C$7:$C$102,A16,'Day Plan'!$H$7:$H$102) -> 62 | E16: =IF(B16=0,0,C16/B16) -> 0
A17: 3 — Polish + onboarding | B17: =COUNTIF('Day Plan'!$C$7:$C$102,A17) -> 13 | C17: =COUNTIFS('Day Plan'!$C$7:$C$102,A17,'Day Plan'!$L$7:$L$102,TRUE()) -> 0 | D17: =SUMIF('Day Plan'!$C$7:$C$102,A17,'Day Plan'!$H$7:$H$102) -> 48 | E17: =IF(B17=0,0,C17/B17) -> 0
A18: 4 — Pre-launch | B18: =COUNTIF('Day Plan'!$C$7:$C$102,A18) -> 22 | C18: =COUNTIFS('Day Plan'!$C$7:$C$102,A18,'Day Plan'!$L$7:$L$102,TRUE()) -> 0 | D18: =SUMIF('Day Plan'!$C$7:$C$102,A18,'Day Plan'!$H$7:$H$102) -> 74 | E18: =IF(B18=0,0,C18/B18) -> 0
A19: 5 — Post-launch | B19: =COUNTIF('Day Plan'!$C$7:$C$102,A19) -> 15 | C19: =COUNTIFS('Day Plan'!$C$7:$C$102,A19,'Day Plan'!$L$7:$L$102,TRUE()) -> 0 | D19: =SUMIF('Day Plan'!$C$7:$C$102,A19,'Day Plan'!$H$7:$H$102) -> 42 | E19: =IF(B19=0,0,C19/B19) -> 0
A22: Hours per day
A23: Day | B23: Hours | C23: Tasks | D23: Tasks done | E23: % complete
A24: 1 | B24: =SUMIF('Day Plan'!$A$7:$A$102,A24,'Day Plan'!$H$7:$H$102) -> 8 | C24: =COUNTIF('Day Plan'!$A$7:$A$102,A24) -> 3 | D24: =COUNTIFS('Day Plan'!$A$7:$A$102,A24,'Day Plan'!$L$7:$L$102,TRUE()) -> 0 | E24: =IF(C24=0,0,D24/C24) -> 0
A25: 2 | B25: =SUMIF('Day Plan'!$A$7:$A$102,A25,'Day Plan'!$H$7:$H$102) -> 7 | C25: =COUNTIF('Day Plan'!$A$7:$A$102,A25) -> 5 | D25: =COUNTIFS('Day Plan'!$A$7:$A$102,A25,'Day Plan'!$L$7:$L$102,TRUE()) -> 0 | E25: =IF(C25=0,0,D25/C25) -> 0
A26: 3 | B26: =SUMIF('Day Plan'!$A$7:$A$102,A26,'Day Plan'!$H$7:$H$102) -> 8 | C26: =COUNTIF('Day Plan'!$A$7:$A$102,A26) -> 3 | D26: =COUNTIFS('Day Plan'!$A$7:$A$102,A26,'Day Plan'!$L$7:$L$102,TRUE()) -> 0 | E26: =IF(C26=0,0,D26/C26) -> 0
A27: 4 | B27: =SUMIF('Day Plan'!$A$7:$A$102,A27,'Day Plan'!$H$7:$H$102) -> 8 | C27: =COUNTIF('Day Plan'!$A$7:$A$102,A27) -> 3 | D27: =COUNTIFS('Day Plan'!$A$7:$A$102,A27,'Day Plan'!$L$7:$L$102,TRUE()) -> 0 | E27: =IF(C27=0,0,D27/C27) -> 0
A28: 5 | B28: =SUMIF('Day Plan'!$A$7:$A$102,A28,'Day Plan'!$H$7:$H$102) -> 8 | C28: =COUNTIF('Day Plan'!$A$7:$A$102,A28) -> 3 | D28: =COUNTIFS('Day Plan'!$A$7:$A$102,A28,'Day Plan'!$L$7:$L$102,TRUE()) -> 0 | E28: =IF(C28=0,0,D28/C28) -> 0
A29: 6 | B29: =SUMIF('Day Plan'!$A$7:$A$102,A29,'Day Plan'!$H$7:$H$102) -> 8 | C29: =COUNTIF('Day Plan'!$A$7:$A$102,A29) -> 5 | D29: =COUNTIFS('Day Plan'!$A$7:$A$102,A29,'Day Plan'!$L$7:$L$102,TRUE()) -> 0 | E29: =IF(C29=0,0,D29/C29) -> 0
A30: 7 | B30: =SUMIF('Day Plan'!$A$7:$A$102,A30,'Day Plan'!$H$7:$H$102) -> 8 | C30: =COUNTIF('Day Plan'!$A$7:$A$102,A30) -> 2 | D30: =COUNTIFS('Day Plan'!$A$7:$A$102,A30,'Day Plan'!$L$7:$L$102,TRUE()) -> 0 | E30: =IF(C30=0,0,D30/C30) -> 0
A31: 8 | B31: =SUMIF('Day Plan'!$A$7:$A$102,A31,'Day Plan'!$H$7:$H$102) -> 8 | C31: =COUNTIF('Day Plan'!$A$7:$A$102,A31) -> 2 | D31: =COUNTIFS('Day Plan'!$A$7:$A$102,A31,'Day Plan'!$L$7:$L$102,TRUE()) -> 0 | E31: =IF(C31=0,0,D31/C31) -> 0
A32: 9 | B32: =SUMIF('Day Plan'!$A$7:$A$102,A32,'Day Plan'!$H$7:$H$102) -> 8 | C32: =COUNTIF('Day Plan'!$A$7:$A$102,A32) -> 3 | D32: =COUNTIFS('Day Plan'!$A$7:$A$102,A32,'Day Plan'!$L$7:$L$102,TRUE()) -> 0 | E32: =IF(C32=0,0,D32/C32) -> 0
A33: 10 | B33: =SUMIF('Day Plan'!$A$7:$A$102,A33,'Day Plan'!$H$7:$H$102) -> 7 | C33: =COUNTIF('Day Plan'!$A$7:$A$102,A33) -> 4 | D33: =COUNTIFS('Day Plan'!$A$7:$A$102,A33,'Day Plan'!$L$7:$L$102,TRUE()) -> 0 | E33: =IF(C33=0,0,D33/C33) -> 0
A34: 11 | B34: =SUMIF('Day Plan'!$A$7:$A$102,A34,'Day Plan'!$H$7:$H$102) -> 7 | C34: =COUNTIF('Day Plan'!$A$7:$A$102,A34) -> 2 | D34: =COUNTIFS('Day Plan'!$A$7:$A$102,A34,'Day Plan'!$L$7:$L$102,TRUE()) -> 0 | E34: =IF(C34=0,0,D34/C34) -> 0
A35: 12 | B35: =SUMIF('Day Plan'!$A$7:$A$102,A35,'Day Plan'!$H$7:$H$102) -> 8 | C35: =COUNTIF('Day Plan'!$A$7:$A$102,A35) -> 3 | D35: =COUNTIFS('Day Plan'!$A$7:$A$102,A35,'Day Plan'!$L$7:$L$102,TRUE()) -> 0 | E35: =IF(C35=0,0,D35/C35) -> 0
... A58: 35 | B58: =SUMIF('Day Plan'!$A$7:$A$102,A58,'Day Plan'!$H$7:$H$102) -> 8 | C58: =COUNTIF('Day Plan'!$A$7:$A$102,A58) -> 3 | D58: =COUNTIFS('Day Plan'!$A$7:$A$102,A58,'Day Plan'!$L$7:$L$102,TRUE()) -> 0 | E58: =IF(C58=0,0,D58/C58) -> 0

Sheet Risk Register
A1: Risk Register
A3: Things that could derail the plan.
A5: Risk | B5: Probability (1-5) | C5: Severity (1-5) | D5: Score | E5: Mitigation
A6: Trademark clearance fails on candidate names | B6: 3 | C6: 4 | D6: =B6*C6 -> 12 | E6: Generate 50+ candidates upfront. Have backups.
A7: Anthropic API rate limits during build | B7: 2 | C7: 3 | D7: =B7*C7 -> 6 | E7: Retry/exponential backoff. Cache aggressively.
A8: Cold-start retention < 20% | B8: 4 | C8: 4 | D8: =B8*C8 -> 16 | E8: Onboarding loop and 10-message preview address this.
A9: Personalization cohort doesn't beat control | B9: 4 | C9: 4 | D9: =B9*C9 -> 16 | E9: Honor the data. Maybe the summary needs to be richer, or the system prompt composition needs work. Iterate before assuming the thesis is wrong.
A10: Feature creep slows launch beyond day 30 | B10: 4 | C10: 3 | D10: =B10*C10 -> 12 | E10: Buffer days absorb 1 week. Beyond that, cut scope.
A11: Founder burnout from solo pace | B11: 3 | C11: 5 | D11: =B11*C11 -> 15 | E11: 5 days/week not 7. Recover on weekends.
A12: Privacy bug — user data leaks or delete fails | B12: 2 | C12: 5 | D12: =B12*C12 -> 10 | E12: Day 25 privacy audit non-negotiable.
A13: Summarization job produces bad summaries | B13: 3 | C13: 3 | D13: =B13*C13 -> 9 | E13: Test prompt thoroughly before launch. Manual review of 50 summaries.
A14: Behavioral logging has bugs corrupting data | B14: 3 | C14: 4 | D14: =B14*C14 -> 12 | E14: Day 15 end-to-end test catches this. Bad data is worse than no data.
A15: Mem0 or Supabase service issues at scale | B15: 2 | C15: 3 | D15: =B15*C15 -> 6 | E15: Free tiers tested at small scale. Have fallback plans.

Sheet Decision Log
A1: Decision Log
A3: Use this whenever you make a real decision.
A5: Date | B5: Decision | C5: Why | D5: What changed in plan
